{
  "cells": [
    {
      "cell_type": "code",
      "source": [
        "!git status"
      ],
      "metadata": {
        "colab": {
          "base_uri": "https://localhost:8080/"
        },
        "id": "tWBeKkT0rgms",
        "outputId": "dccc2441-84f7-409d-b0a9-35fbd8574e50"
      },
      "execution_count": 1,
      "outputs": [
        {
          "output_type": "stream",
          "name": "stdout",
          "text": [
            "fatal: not a git repository (or any of the parent directories): .git\n"
          ]
        }
      ]
    },
    {
      "cell_type": "code",
      "source": [
        "pwd"
      ],
      "metadata": {
        "colab": {
          "base_uri": "https://localhost:8080/",
          "height": 35
        },
        "id": "vIbbqx4_rxRH",
        "outputId": "b1bffc5d-6cdf-4fda-f8ff-1537f078a6d6"
      },
      "execution_count": 2,
      "outputs": [
        {
          "output_type": "execute_result",
          "data": {
            "text/plain": [
              "'/content'"
            ],
            "application/vnd.google.colaboratory.intrinsic+json": {
              "type": "string"
            }
          },
          "metadata": {},
          "execution_count": 2
        }
      ]
    },
    {
      "cell_type": "code",
      "source": [
        ""
      ],
      "metadata": {
        "id": "Gb7hS3_IsqlH"
      },
      "execution_count": null,
      "outputs": []
    },
    {
      "cell_type": "code",
      "execution_count": null,
      "metadata": {
        "colab": {
          "base_uri": "https://localhost:8080/"
        },
        "id": "kQwSpl7Kp5c0",
        "outputId": "602691dc-2d60-4e8d-e201-0662ac63592e"
      },
      "outputs": [
        {
          "output_type": "stream",
          "name": "stdout",
          "text": [
            "Mounted at /content/drive\n"
          ]
        }
      ],
      "source": [
        "from google.colab import drive\n",
        "drive.mount('/content/drive')\n"
      ]
    },
    {
      "cell_type": "code",
      "source": [
        "import tensorflow as tf\n",
        "from tensorflow.keras.models import Model\n",
        "from tensorflow.keras.layers import Dense, GlobalAveragePooling2D, Dropout\n",
        "from tensorflow.keras.applications import Xception\n",
        "from tensorflow.keras.preprocessing.image import ImageDataGenerator\n",
        "from tensorflow.keras.optimizers import Adam\n",
        "from tensorflow.keras.callbacks import ModelCheckpoint\n"
      ],
      "metadata": {
        "id": "19JxG4V-rp1S"
      },
      "execution_count": null,
      "outputs": []
    },
    {
      "cell_type": "code",
      "execution_count": null,
      "metadata": {
        "colab": {
          "base_uri": "https://localhost:8080/"
        },
        "id": "8B6OQDwMqjBi",
        "outputId": "5b1d46a8-d86f-4a33-8dbe-91c17e823090"
      },
      "outputs": [
        {
          "output_type": "stream",
          "name": "stdout",
          "text": [
            "Found 5712 images belonging to 4 classes.\n",
            "Found 1314 images belonging to 4 classes.\n"
          ]
        }
      ],
      "source": [
        "# Hyperparameters\n",
        "batch_size = 32\n",
        "image_size = (224, 224)\n",
        "\n",
        "# Training data generator with augmentation\n",
        "train_datagen = ImageDataGenerator(\n",
        "    rescale=1./255,\n",
        "    rotation_range=30,\n",
        "    width_shift_range=0.3,\n",
        "    height_shift_range=0.3,\n",
        "    shear_range=0.3,\n",
        "    zoom_range=0.3,\n",
        "    horizontal_flip=True,\n",
        "    fill_mode='nearest'\n",
        ")\n",
        "\n",
        "train_generator = train_datagen.flow_from_directory(\n",
        "    '/content/drive/MyDrive/Training Data',  # Path to training data\n",
        "    target_size=image_size,\n",
        "    batch_size=batch_size,\n",
        "    class_mode='categorical'\n",
        ")\n",
        "\n",
        "# Testing data generator without augmentation\n",
        "test_datagen = ImageDataGenerator(rescale=1./255)\n",
        "\n",
        "test_generator = test_datagen.flow_from_directory(\n",
        "    ' ',  # Path to testing data\n",
        "    target_size=image_size,\n",
        "    batch_size=batch_size,\n",
        "    class_mode='categorical'\n",
        ")\n"
      ]
    },
    {
      "cell_type": "code",
      "execution_count": null,
      "metadata": {
        "colab": {
          "base_uri": "https://localhost:8080/"
        },
        "id": "_z_45A8RrDQW",
        "outputId": "3f76cdbe-3e85-4ca4-8ee7-98dd46f8c4fa"
      },
      "outputs": [
        {
          "output_type": "stream",
          "name": "stdout",
          "text": [
            "Downloading data from https://storage.googleapis.com/tensorflow/keras-applications/xception/xception_weights_tf_dim_ordering_tf_kernels_notop.h5\n",
            "\u001b[1m83683744/83683744\u001b[0m \u001b[32m━━━━━━━━━━━━━━━━━━━━\u001b[0m\u001b[37m\u001b[0m \u001b[1m0s\u001b[0m 0us/step\n"
          ]
        }
      ],
      "source": [
        "# Load Xception as base model (excluding top layers)\n",
        "base_model = Xception(weights='imagenet', include_top=False, input_shape=(224, 224, 3))\n",
        "\n",
        "# Add custom layers on top of Xception\n",
        "x = base_model.output\n",
        "x = GlobalAveragePooling2D()(x)\n",
        "x = Dense(1024, activation='relu')(x)\n",
        "x = Dropout(0.5)(x)\n",
        "predictions = Dense(4, activation='softmax')(x)  # 4 classes: Glioma, Meningioma, Pituitary, NoTumor\n",
        "\n",
        "# Create the full model\n",
        "model = Model(inputs=base_model.input, outputs=predictions)\n",
        "\n",
        "# Freeze the base model layers\n",
        "for layer in base_model.layers:\n",
        "    layer.trainable = False\n",
        "\n",
        "# Compile the model\n",
        "model.compile(optimizer=Adam(learning_rate=1e-4), loss='categorical_crossentropy', metrics=['accuracy'])\n"
      ]
    },
    {
      "cell_type": "code",
      "execution_count": null,
      "metadata": {
        "colab": {
          "base_uri": "https://localhost:8080/",
          "height": 1000
        },
        "id": "cIXds2-0rHpu",
        "outputId": "a9bffaa9-60bc-4186-8aee-e230c1cf1627"
      },
      "outputs": [
        {
          "output_type": "stream",
          "name": "stdout",
          "text": [
            "Epoch 1/10\n"
          ]
        },
        {
          "output_type": "stream",
          "name": "stderr",
          "text": [
            "/usr/local/lib/python3.10/dist-packages/keras/src/trainers/data_adapters/py_dataset_adapter.py:121: UserWarning: Your `PyDataset` class should call `super().__init__(**kwargs)` in its constructor. `**kwargs` can include `workers`, `use_multiprocessing`, `max_queue_size`. Do not pass these arguments to `fit()`, as they will be ignored.\n",
            "  self._warn_if_super_not_called()\n"
          ]
        },
        {
          "output_type": "stream",
          "name": "stdout",
          "text": [
            "\u001b[1m 37/178\u001b[0m \u001b[32m━━━━\u001b[0m\u001b[37m━━━━━━━━━━━━━━━━\u001b[0m \u001b[1m15:48\u001b[0m 7s/step - accuracy: 0.4468 - loss: 1.2415"
          ]
        },
        {
          "output_type": "error",
          "ename": "UnknownError",
          "evalue": "Graph execution error:\n\nDetected at node PyFunc defined at (most recent call last):\n<stack traces unavailable>\nDetected at node PyFunc defined at (most recent call last):\n<stack traces unavailable>\n2 root error(s) found.\n  (0) UNKNOWN:  FileNotFoundError: [Errno 2] No such file or directory: '/content/drive/MyDrive/Training Data/glioma/Tr-gl_0572.jpg'\nTraceback (most recent call last):\n\n  File \"/usr/local/lib/python3.10/dist-packages/tensorflow/python/ops/script_ops.py\", line 270, in __call__\n    ret = func(*args)\n\n  File \"/usr/local/lib/python3.10/dist-packages/tensorflow/python/autograph/impl/api.py\", line 643, in wrapper\n    return func(*args, **kwargs)\n\n  File \"/usr/local/lib/python3.10/dist-packages/tensorflow/python/data/ops/from_generator_op.py\", line 198, in generator_py_func\n    values = next(generator_state.get_iterator(iterator_id))\n\n  File \"/usr/local/lib/python3.10/dist-packages/keras/src/trainers/data_adapters/py_dataset_adapter.py\", line 260, in _get_iterator\n    for i, batch in enumerate(gen_fn()):\n\n  File \"/usr/local/lib/python3.10/dist-packages/keras/src/trainers/data_adapters/py_dataset_adapter.py\", line 253, in generator_fn\n    yield self.py_dataset[i]\n\n  File \"/usr/local/lib/python3.10/dist-packages/keras/src/legacy/preprocessing/image.py\", line 68, in __getitem__\n    return self._get_batches_of_transformed_samples(index_array)\n\n  File \"/usr/local/lib/python3.10/dist-packages/keras/src/legacy/preprocessing/image.py\", line 313, in _get_batches_of_transformed_samples\n    img = image_utils.load_img(\n\n  File \"/usr/local/lib/python3.10/dist-packages/keras/src/utils/image_utils.py\", line 235, in load_img\n    with open(path, \"rb\") as f:\n\nFileNotFoundError: [Errno 2] No such file or directory: '/content/drive/MyDrive/Training Data/glioma/Tr-gl_0572.jpg'\n\n\n\t [[{{node PyFunc}}]]\n\t [[IteratorGetNext]]\n\t [[IteratorGetNext/_2]]\n  (1) UNKNOWN:  FileNotFoundError: [Errno 2] No such file or directory: '/content/drive/MyDrive/Training Data/glioma/Tr-gl_0572.jpg'\nTraceback (most recent call last):\n\n  File \"/usr/local/lib/python3.10/dist-packages/tensorflow/python/ops/script_ops.py\", line 270, in __call__\n    ret = func(*args)\n\n  File \"/usr/local/lib/python3.10/dist-packages/tensorflow/python/autograph/impl/api.py\", line 643, in wrapper\n    return func(*args, **kwargs)\n\n  File \"/usr/local/lib/python3.10/dist-packages/tensorflow/python/data/ops/from_generator_op.py\", line 198, in generator_py_func\n    values = next(generator_state.get_iterator(iterator_id))\n\n  File \"/usr/local/lib/python3.10/dist-packages/keras/src/trainers/data_adapters/py_dataset_adapter.py\", line 260, in _get_iterator\n    for i, batch in enumerate(gen_fn()):\n\n  File \"/usr/local/lib/python3.10/dist-packages/keras/src/trainers/data_adapters/py_dataset_adapter.py\", line 253, in generator_fn\n    yield self.py_dataset[i]\n\n  File \"/usr/local/lib/python3.10/dist-packages/keras/src/legacy/preprocessing/image.py\", line 68, in __getitem__\n    return self._get_batches_of_transformed_samples(index_array)\n\n  File \"/usr/local/lib/python3.10/dist-packages/keras/src/legacy/preprocessing/image.py\", line 313, in _get_batches_of_transformed_samples\n    img = image_utils.load_img(\n\n  File \"/usr/local/lib/python3.10/dist-packages/keras/src/utils/image_utils.py\", line 235, in load_img\n    with open(path, \"rb\") as f:\n\nFileNotFoundError: [Errno 2] No such file or directory: '/content/drive/MyDrive/Training Data/glioma/Tr-gl_0572.jpg'\n\n\n\t [[{{node PyFunc}}]]\n\t [[IteratorGetNext]]\n0 successful operations.\n0 derived errors ignored. [Op:__inference_one_step_on_iterator_7998]",
          "traceback": [
            "\u001b[0;31m---------------------------------------------------------------------------\u001b[0m",
            "\u001b[0;31mUnknownError\u001b[0m                              Traceback (most recent call last)",
            "\u001b[0;32m<ipython-input-6-0847178f5813>\u001b[0m in \u001b[0;36m<cell line: 2>\u001b[0;34m()\u001b[0m\n\u001b[1;32m      1\u001b[0m \u001b[0;31m# Train the model (initial training, only top layers)\u001b[0m\u001b[0;34m\u001b[0m\u001b[0;34m\u001b[0m\u001b[0m\n\u001b[0;32m----> 2\u001b[0;31m history = model.fit(\n\u001b[0m\u001b[1;32m      3\u001b[0m     \u001b[0mtrain_generator\u001b[0m\u001b[0;34m,\u001b[0m\u001b[0;34m\u001b[0m\u001b[0;34m\u001b[0m\u001b[0m\n\u001b[1;32m      4\u001b[0m     \u001b[0mepochs\u001b[0m\u001b[0;34m=\u001b[0m\u001b[0;36m10\u001b[0m\u001b[0;34m,\u001b[0m  \u001b[0;31m# Train for a few epochs before fine-tuning\u001b[0m\u001b[0;34m\u001b[0m\u001b[0;34m\u001b[0m\u001b[0m\n\u001b[1;32m      5\u001b[0m     \u001b[0msteps_per_epoch\u001b[0m\u001b[0;34m=\u001b[0m\u001b[0mtrain_generator\u001b[0m\u001b[0;34m.\u001b[0m\u001b[0msamples\u001b[0m \u001b[0;34m//\u001b[0m \u001b[0mbatch_size\u001b[0m\u001b[0;34m,\u001b[0m\u001b[0;34m\u001b[0m\u001b[0;34m\u001b[0m\u001b[0m\n",
            "\u001b[0;32m/usr/local/lib/python3.10/dist-packages/keras/src/utils/traceback_utils.py\u001b[0m in \u001b[0;36merror_handler\u001b[0;34m(*args, **kwargs)\u001b[0m\n\u001b[1;32m    120\u001b[0m             \u001b[0;31m# To get the full stack trace, call:\u001b[0m\u001b[0;34m\u001b[0m\u001b[0;34m\u001b[0m\u001b[0m\n\u001b[1;32m    121\u001b[0m             \u001b[0;31m# `keras.config.disable_traceback_filtering()`\u001b[0m\u001b[0;34m\u001b[0m\u001b[0;34m\u001b[0m\u001b[0m\n\u001b[0;32m--> 122\u001b[0;31m             \u001b[0;32mraise\u001b[0m \u001b[0me\u001b[0m\u001b[0;34m.\u001b[0m\u001b[0mwith_traceback\u001b[0m\u001b[0;34m(\u001b[0m\u001b[0mfiltered_tb\u001b[0m\u001b[0;34m)\u001b[0m \u001b[0;32mfrom\u001b[0m \u001b[0;32mNone\u001b[0m\u001b[0;34m\u001b[0m\u001b[0;34m\u001b[0m\u001b[0m\n\u001b[0m\u001b[1;32m    123\u001b[0m         \u001b[0;32mfinally\u001b[0m\u001b[0;34m:\u001b[0m\u001b[0;34m\u001b[0m\u001b[0;34m\u001b[0m\u001b[0m\n\u001b[1;32m    124\u001b[0m             \u001b[0;32mdel\u001b[0m \u001b[0mfiltered_tb\u001b[0m\u001b[0;34m\u001b[0m\u001b[0;34m\u001b[0m\u001b[0m\n",
            "\u001b[0;32m/usr/local/lib/python3.10/dist-packages/tensorflow/python/eager/execute.py\u001b[0m in \u001b[0;36mquick_execute\u001b[0;34m(op_name, num_outputs, inputs, attrs, ctx, name)\u001b[0m\n\u001b[1;32m     51\u001b[0m   \u001b[0;32mtry\u001b[0m\u001b[0;34m:\u001b[0m\u001b[0;34m\u001b[0m\u001b[0;34m\u001b[0m\u001b[0m\n\u001b[1;32m     52\u001b[0m     \u001b[0mctx\u001b[0m\u001b[0;34m.\u001b[0m\u001b[0mensure_initialized\u001b[0m\u001b[0;34m(\u001b[0m\u001b[0;34m)\u001b[0m\u001b[0;34m\u001b[0m\u001b[0;34m\u001b[0m\u001b[0m\n\u001b[0;32m---> 53\u001b[0;31m     tensors = pywrap_tfe.TFE_Py_Execute(ctx._handle, device_name, op_name,\n\u001b[0m\u001b[1;32m     54\u001b[0m                                         inputs, attrs, num_outputs)\n\u001b[1;32m     55\u001b[0m   \u001b[0;32mexcept\u001b[0m \u001b[0mcore\u001b[0m\u001b[0;34m.\u001b[0m\u001b[0m_NotOkStatusException\u001b[0m \u001b[0;32mas\u001b[0m \u001b[0me\u001b[0m\u001b[0;34m:\u001b[0m\u001b[0;34m\u001b[0m\u001b[0;34m\u001b[0m\u001b[0m\n",
            "\u001b[0;31mUnknownError\u001b[0m: Graph execution error:\n\nDetected at node PyFunc defined at (most recent call last):\n<stack traces unavailable>\nDetected at node PyFunc defined at (most recent call last):\n<stack traces unavailable>\n2 root error(s) found.\n  (0) UNKNOWN:  FileNotFoundError: [Errno 2] No such file or directory: '/content/drive/MyDrive/Training Data/glioma/Tr-gl_0572.jpg'\nTraceback (most recent call last):\n\n  File \"/usr/local/lib/python3.10/dist-packages/tensorflow/python/ops/script_ops.py\", line 270, in __call__\n    ret = func(*args)\n\n  File \"/usr/local/lib/python3.10/dist-packages/tensorflow/python/autograph/impl/api.py\", line 643, in wrapper\n    return func(*args, **kwargs)\n\n  File \"/usr/local/lib/python3.10/dist-packages/tensorflow/python/data/ops/from_generator_op.py\", line 198, in generator_py_func\n    values = next(generator_state.get_iterator(iterator_id))\n\n  File \"/usr/local/lib/python3.10/dist-packages/keras/src/trainers/data_adapters/py_dataset_adapter.py\", line 260, in _get_iterator\n    for i, batch in enumerate(gen_fn()):\n\n  File \"/usr/local/lib/python3.10/dist-packages/keras/src/trainers/data_adapters/py_dataset_adapter.py\", line 253, in generator_fn\n    yield self.py_dataset[i]\n\n  File \"/usr/local/lib/python3.10/dist-packages/keras/src/legacy/preprocessing/image.py\", line 68, in __getitem__\n    return self._get_batches_of_transformed_samples(index_array)\n\n  File \"/usr/local/lib/python3.10/dist-packages/keras/src/legacy/preprocessing/image.py\", line 313, in _get_batches_of_transformed_samples\n    img = image_utils.load_img(\n\n  File \"/usr/local/lib/python3.10/dist-packages/keras/src/utils/image_utils.py\", line 235, in load_img\n    with open(path, \"rb\") as f:\n\nFileNotFoundError: [Errno 2] No such file or directory: '/content/drive/MyDrive/Training Data/glioma/Tr-gl_0572.jpg'\n\n\n\t [[{{node PyFunc}}]]\n\t [[IteratorGetNext]]\n\t [[IteratorGetNext/_2]]\n  (1) UNKNOWN:  FileNotFoundError: [Errno 2] No such file or directory: '/content/drive/MyDrive/Training Data/glioma/Tr-gl_0572.jpg'\nTraceback (most recent call last):\n\n  File \"/usr/local/lib/python3.10/dist-packages/tensorflow/python/ops/script_ops.py\", line 270, in __call__\n    ret = func(*args)\n\n  File \"/usr/local/lib/python3.10/dist-packages/tensorflow/python/autograph/impl/api.py\", line 643, in wrapper\n    return func(*args, **kwargs)\n\n  File \"/usr/local/lib/python3.10/dist-packages/tensorflow/python/data/ops/from_generator_op.py\", line 198, in generator_py_func\n    values = next(generator_state.get_iterator(iterator_id))\n\n  File \"/usr/local/lib/python3.10/dist-packages/keras/src/trainers/data_adapters/py_dataset_adapter.py\", line 260, in _get_iterator\n    for i, batch in enumerate(gen_fn()):\n\n  File \"/usr/local/lib/python3.10/dist-packages/keras/src/trainers/data_adapters/py_dataset_adapter.py\", line 253, in generator_fn\n    yield self.py_dataset[i]\n\n  File \"/usr/local/lib/python3.10/dist-packages/keras/src/legacy/preprocessing/image.py\", line 68, in __getitem__\n    return self._get_batches_of_transformed_samples(index_array)\n\n  File \"/usr/local/lib/python3.10/dist-packages/keras/src/legacy/preprocessing/image.py\", line 313, in _get_batches_of_transformed_samples\n    img = image_utils.load_img(\n\n  File \"/usr/local/lib/python3.10/dist-packages/keras/src/utils/image_utils.py\", line 235, in load_img\n    with open(path, \"rb\") as f:\n\nFileNotFoundError: [Errno 2] No such file or directory: '/content/drive/MyDrive/Training Data/glioma/Tr-gl_0572.jpg'\n\n\n\t [[{{node PyFunc}}]]\n\t [[IteratorGetNext]]\n0 successful operations.\n0 derived errors ignored. [Op:__inference_one_step_on_iterator_7998]"
          ]
        }
      ],
      "source": [
        "# Train the model (initial training, only top layers)\n",
        "history = model.fit(\n",
        "    train_generator,\n",
        "    epochs=10,  # Train for a few epochs before fine-tuning\n",
        "    steps_per_epoch=train_generator.samples // batch_size,\n",
        "    validation_data=test_generator,\n",
        "    validation_steps=test_generator.samples // batch_size,\n",
        "    verbose=1\n",
        ")\n"
      ]
    },
    {
      "cell_type": "code",
      "source": [
        "# Unfreeze the base model layers for fine-tuning\n",
        "for layer in base_model.layers:\n",
        "    layer.trainable = True\n",
        "\n",
        "# Re-compile the model with a lower learning rate\n",
        "model.compile(optimizer=Adam(learning_rate=1e-5), loss='categorical_crossentropy', metrics=['accuracy'])\n",
        "\n",
        "# Fine-tune the model\n",
        "history_fine = model.fit(\n",
        "    train_generator,\n",
        "    epochs=10,  # Continue training for more epochs\n",
        "    steps_per_epoch=train_generator.samples // batch_size,\n",
        "    validation_data=test_generator,\n",
        "    validation_steps=test_generator.samples // batch_size,\n",
        "    verbose=1\n",
        ")\n"
      ],
      "metadata": {
        "id": "MRV6xIs3pY5x"
      },
      "execution_count": null,
      "outputs": []
    },
    {
      "cell_type": "code",
      "source": [
        "# Evaluate the model on the test set\n",
        "test_loss, test_acc = model.evaluate(test_generator, steps=test_generator.samples // batch_size)\n",
        "print(f\"Test Accuracy: {test_acc * 100:.2f}%\")\n",
        "print(f\"Test Loss: {test_loss:.4f}\")\n"
      ],
      "metadata": {
        "id": "PNzCy-FtpccM"
      },
      "execution_count": null,
      "outputs": []
    },
    {
      "cell_type": "code",
      "source": [
        "# Save the model after training\n",
        "model.save('tumor_classifier_xception_finetuned.keras')\n"
      ],
      "metadata": {
        "id": "S8Z4ipcOpeeR"
      },
      "execution_count": null,
      "outputs": []
    },
    {
      "cell_type": "code",
      "source": [
        "# Optional: Save the best model during training\n",
        "checkpoint = ModelCheckpoint('best_model.h5', monitor='val_accuracy', save_best_only=True, mode='max')\n",
        "\n",
        "# Optional: Reduce learning rate when validation accuracy plateaus\n",
        "reduce_lr = tf.keras.callbacks.ReduceLROnPlateau(monitor='val_loss', factor=0.2, patience=3, min_lr=1e-7)\n",
        "\n",
        "# Re-train with callbacks\n",
        "history = model.fit(\n",
        "    train_generator,\n",
        "    epochs=10,\n",
        "    steps_per_epoch=train_generator.samples // batch_size,\n",
        "    validation_data=test_generator,\n",
        "    validation_steps=test_generator.samples // batch_size,\n",
        "    verbose=1,\n",
        "    callbacks=[checkpoint, reduce_lr]\n",
        ")\n"
      ],
      "metadata": {
        "id": "Zel34f42pj35"
      },
      "execution_count": null,
      "outputs": []
    }
  ],
  "metadata": {
    "accelerator": "GPU",
    "colab": {
      "gpuType": "T4",
      "provenance": []
    },
    "kernelspec": {
      "display_name": "Python 3",
      "name": "python3"
    },
    "language_info": {
      "name": "python"
    }
  },
  "nbformat": 4,
  "nbformat_minor": 0
}